Workbook
Name AccountDesc: GLData!#REF!
Name AccountDesc: GLDataRename!#REF!
Name AccountDesc: '[1]GL Data'!#REF!
Name AccountDesc: 'Full GL Data'!#REF!
Name AmountFrom: GLData!#REF!
Name AmountFrom: GLDataRename!#REF!
Name AmountFrom: '[1]GL Data'!#REF!
Name AmountFrom: 'Full GL Data'!#REF!
Name AmountTo: GLData!#REF!
Name AmountTo: GLDataRename!#REF!
Name AmountTo: '[1]GL Data'!#REF!
Name AmountTo: 'Full GL Data'!#REF!
Name Company: GLData!#REF!
Name Company: GLDataRename!#REF!
Name Company: '[1]GL Data'!#REF!
Name Company: 'Full GL Data'!#REF!
Name CurrentMonth: GLData!#REF!
Name CurrentMonth: GLDataRename!#REF!
Name CurrentMonth: 'Full GL Data'!#REF!
Name DateBegin: GLData!#REF!
Name DateBegin: GLDataRename!#REF!
Name DateBegin: '[1]GL Data'!#REF!
Name DateBegin: 'Full GL Data'!#REF!
Name DateEnd: GLData!#REF!
Name DateEnd: GLDataRename!#REF!
Name DateEnd: '[1]GL Data'!#REF!
Name DateEnd: 'Full GL Data'!#REF!
Name District: 'PL Example'!#REF!
Name DistrictName: 'PL Example'!#REF!
Name ExcludeIC: 'PL Example'!#REF!
Name ExcludeIC: #REF!
Name FromMonth: GLData!#REF!
Name FromMonth: GLDataRename!#REF!
Name FromMonth: 'Full GL Data'!#REF!
Name FullAccount: GLData!#REF!
Name FullAccount: GLDataRename!#REF!
Name FullAccount: '[1]GL Data'!#REF!
Name FullAccount: 'Full GL Data'!#REF!
Name JournalNum: GLData!#REF!
Name JournalNum: GLDataRename!#REF!
Name JournalNum: 'Full GL Data'!#REF!
Name Lookup_JE: #REF!
Name Lookup_RM: #REF!
Name Organization: GLData!#REF!
Name Organization: GLDataRename!#REF!
Name Organization: '[1]GL Data'!#REF!
Name Organization: 'Full GL Data'!#REF!
Name OutputToHere: #REF!
Name Posting: GLData!#REF!
Name Posting: GLDataRename!#REF!
Name Posting: '[1]GL Data'!#REF!
Name Posting: 'Full GL Data'!#REF!
Name ReturnMessage: GLData!#REF!
Name ReturnMessage: GLDataRename!#REF!
Name ReturnMessage: '[1]GL Data'!$L$11
Name ReturnMessage: 'Full GL Data'!$L$1
Name Segment1: GLData!#REF!
Name Segment1: GLDataRename!#REF!
Name Segment1: '[1]GL Data'!#REF!
Name Segment1: 'Full GL Data'!#REF!

Sheet GLData
B3: {=_xll.jDataSource(B19:J2804, B18:J18,,"GL_Detail")} -> jDataSource|GLData!$B$3|GL_Detail | E3: =jDataSource(B19:J2804, B18:J18,,"GL_Detail")
B4: {=_xll.jDataSource(B9:C12, B8:C8,,"Dist_Types")} -> jDataSource|GLData!$B$4|Dist_Types | E4: =jDataSource(B9:C12, B8:C8,,"Dist_Types")
B7: Dist Types In Sheet | E7: DIST Descs | F7: {=_xll.jQuery(GLData!B3, "SELECT * FROM @1 GROUP BY Description")} -> jQuery|GLData!$F$7
B8: Dist | C8: Type | F8: {=_xll.jDropdown(F7,,,_xll.PairGroup(_xll.Pair("Account",F11),_xll.Pair("Description",F12),_xll.Pair("Dist",F13)),"Description")} -> > jDropdown is ready for multi target.
B9: 7001 | C9: Landfill | F9: CLICK ME
B10: 7002 | C10: Hauling
B11: 7004 | C11: Landfill | E11: Account: | F11: 51260
B12: 7005 | C12: Hauling | E12: Desc: | F12: Depreciation Expense
E13: Dist: | F13: 7001
B17: GL Detail Data In Sheet | I17: Total | J17: =SUBTOTAL(9,J19:J2807) -> -71374.001
B18: Posted | C18: Year Mth | D18: Full Account | E18: Account | F18: Account Desc | H18: Description | I18: Dist | J18: Amount | S18: Syst | T18: SubS | U18: Journal | V18: Journal Description | W18: Line Description
B19: 37272 | C19: 2002-01 | D19: 52120-7001-000-00 | E19: 52120 | F19: Parts and Materials Overhead Unal | H19: Repairs and Maint | I19: 7001 | J19: 50.12 | S19: 000 | T19: 00 | U19: JRNLWA00030958 | V19: From Voucher Posting. | W19: suas Auto adhuc
B20: 37272 | C20: 2002-01 | D20: 52120-7001-000-00 | E20: 52120 | F20: Parts and Materials Overhead Unal | H20: Repairs and Maint | I20: 7001 | J20: 59.46 | S20: 000 | T20: 00 | U20: JRNLWA00030958 | V20: From Voucher Posting. | W20: odio Auto audis
B21: 37272 | C21: 2002-01 | D21: 52120-7001-000-00 | E21: 52120 | F21: Parts and Materials Overhead Unal | H21: Repairs and Maint | I21: 7001 | J21: 17.71 | S21: 000 | T21: 00 | U21: JRNLWA00030958 | V21: From Voucher Posting. | W21: pede Auto dicit
B22: 37272 | C22: 2002-01 | D22: 52120-7001-000-00 | E22: 52120 | F22: Parts and Materials Overhead Unal | H22: Repairs and Maint | I22: 7001 | J22: 47.17 | S22: 000 | T22: 00 | U22: JRNLWA00030958 | V22: From Voucher Posting. | W22: City of Union vim
B23: 37272 | C23: 2002-01 | D23: 52125-7001-000-00 | E23: 52125 | F23: Operating Supplies Overhead Unall | H23: Repairs and Maint | I23: 7001 | J23: 55.04 | S23: 000 | T23: 00 | U23: JRNLWA00030958 | V23: From Voucher Posting. | W23: inquam inermis gravida Inc
B24: 37272 | C24: 2002-01 | D24: 52125-7001-000-00 | E24: 52125 | F24: Operating Supplies Overhead Unall | H24: Repairs and Maint | I24: 7001 | J24: 92.86 | S24: 000 | T24: 00 | U24: JRNLWA00030958 | V24: From Voucher Posting. | W24: ignota delenit debitis Inc
B25: 37272 | C25: 2002-01 | D25: 52125-7001-000-00 | E25: 52125 | F25: Operating Supplies Overhead Unall | H25: Repairs and Maint | I25: 7001 | J25: 42.64 | S25: 000 | T25: 00 | U25: JRNLWA00030958 | V25: From Voucher Posting. | W25: latine invidunt nam Auto massa
B26: 37272 | C26: 2002-01 | D26: 52142-7001-000-00 | E26: 52142 | F26: Fuel Expense Overhead Unallocated | H26: Repairs and Maint | I26: 7001 | J26: 12.66 | S26: 000 | T26: 00 | U26: JRNLWA00030958 | V26: From Voucher Posting. | W26: audiam quas
B27: 37272 | C27: 2002-01 | D27: 52150-7001-000-00 | E27: 52150 | F27: Utilities Overhead Unallocated | H27: Facility Expense | I27: 7001 | J27: 153.72 | S27: 000 | T27: 00 | U27: JRNLWA00030958 | V27: From Voucher Posting. | W27: labitur lacus
B28: 37272 | C28: 2002-01 | D28: 52150-7001-000-00 | E28: 52150 | F28: Utilities Overhead Unallocated | H28: Facility Expense | I28: 7001 | J28: 201.23 | S28: 000 | T28: 00 | U28: JRNLWA00030958 | V28: From Voucher Posting. | W28: blandit iacet
B29: 37272 | C29: 2002-01 | D29: 52165-7001-000-00 | E29: 52165 | F29: Communications Overhead Unallocat | H29: Facility Expense | I29: 7001 | J29: 97.2 | S29: 000 | T29: 00 | U29: JRNLWA00030958 | V29: From Voucher Posting. | W29: dicam saepius duo Inc
B30: 37272 | C30: 2002-01 | D30: 52200-7001-000-00 | E30: 52200 | F30: Office Supply and Equip Overhead | H30: Facility Expense | I30: 7001 | J30: 5.38 | S30: 000 | T30: 00 | U30: JRNLWA00030958 | V30: From Voucher Posting. | W30: delenit Washington ipsum belle
... B1411: 37407 | C1411: 2002-05 | D1411: 80099-7002-000-00 | E1411: 80099 | F1411: Interest Allocation Overhead Un | H1411: Interest Expense | I1411: 7002 | J1411: -695.12 | S1411: 000 | T1411: 00 | U1411: JRNLWA00035419 | V1411: Interest Allocation | W1411: Feb Interest Allocation
B1412: 37272 | C1412: 2002-01 | D1412: 52120-7001-000-00 | E1412: 52120 | F1412: Parts and Materials Overhead Unal | H1412: Repairs and Maint | I1412: 7004 | J1412: 47.40871 | S1412: 000 | T1412: 00
B1413: 37272 | C1413: 2002-01 | D1413: 52120-7001-000-00 | E1413: 52120 | F1413: Parts and Materials Overhead Unal | H1413: Repairs and Maint | I1413: 7004 | J1413: 63.898717 | S1413: 000 | T1413: 00
B1414: 37272 | C1414: 2002-01 | D1414: 52120-7001-000-00 | E1414: 52120 | F1414: Parts and Materials Overhead Unal | H1414: Repairs and Maint | I1414: 7004 | J1414: 20.171477 | S1414: 000 | T1414: 00
B1415: 37272 | C1415: 2002-01 | D1415: 52120-7001-000-00 | E1415: 52120 | F1415: Parts and Materials Overhead Unal | H1415: Repairs and Maint | I1415: 7004 | J1415: 52.103143 | S1415: 000 | T1415: 00
B1416: 37272 | C1416: 2002-01 | D1416: 52125-7001-000-00 | E1416: 52125 | F1416: Operating Supplies Overhead Unall | H1416: Repairs and Maint | I1416: 7004 | J1416: 53.285391 | S1416: 000 | T1416: 00
B1417: 37272 | C1417: 2002-01 | D1417: 52125-7001-000-00 | E1417: 52125 | F1417: Operating Supplies Overhead Unall | H1417: Repairs and Maint | I1417: 7004 | J1417: 98.482024 | S1417: 000 | T1417: 00
B1418: 37272 | C1418: 2002-01 | D1418: 52125-7001-000-00 | E1418: 52125 | F1418: Operating Supplies Overhead Unall | H1418: Repairs and Maint | I1418: 7004 | J1418: 35.410978 | S1418: 000 | T1418: 00
B1419: 37272 | C1419: 2002-01 | D1419: 52142-7001-000-00 | E1419: 52142 | F1419: Fuel Expense Overhead Unallocated | H1419: Repairs and Maint | I1419: 7004 | J1419: 15.107386 | S1419: 000 | T1419: 00
B1420: 37272 | C1420: 2002-01 | D1420: 52150-7001-000-00 | E1420: 52150 | F1420: Utilities Overhead Unallocated | H1420: Facility Expense | I1420: 7004 | J1420: 144.68466 | S1420: 000 | T1420: 00
B1421: 37272 | C1421: 2002-01 | D1421: 52150-7001-000-00 | E1421: 52150 | F1421: Utilities Overhead Unallocated | H1421: Facility Expense | I1421: 7004 | J1421: 231.44271 | S1421: 000 | T1421: 00
B1422: 37272 | C1422: 2002-01 | D1422: 52165-7001-000-00 | E1422: 52165 | F1422: Communications Overhead Unallocat | H1422: Facility Expense | I1422: 7004 | J1422: 111.63661 | S1422: 000 | T1422: 00
B1423: 37272 | C1423: 2002-01 | D1423: 52200-7001-000-00 | E1423: 52200 | F1423: Office Supply and Equip Overhead | H1423: Facility Expense | I1423: 7004 | J1423: 5.3110801 | S1423: 000 | T1423: 00
... B2804: 37407 | C2804: 2002-05 | D2804: 80099-7002-000-00 | E2804: 80099 | F2804: Interest Allocation Overhead Un | H2804: Interest Expense | I2804: 7005 | J2804: -691.21402 | S2804: 000 | T2804: 00
B2807: End of List
B2810: 37315 | C2810: 2002-02 | D2810: 31000-7002-000-00 | E2810: 31000 | F2810: Hauling Revenue - Roll Off Permanent Che
B2811: 37315 | C2811: 2002-02 | D2811: 31000-7002-000-00 | E2811: 31000 | F2811: Hauling Revenue - Roll Off Permanent Che
...

Sheet Pull
B1: 37272 | C1: 2002-01 | D1: 52120-7001-000-00 | E1: 52120 | F1: Parts and Materials Overhead Unal | G1: Repairs and Maint | H1: 7001 | I1: 12431.12
B3: Goal: | C3: Pull the full dataset from jDataSource on the GLData sheet
B5: {=_xll.ReportRange(GLData!B3,B7:I8,B6:I6,B1:I1)} -> OK!: ReportRange Formula OK [jAction{}]
B6: Posted | C6: Year Mth | D6: Full Account | E6: Account | F6: Account Desc | G6: Description | H6: Dist | I6: Amount

Sheet Filtered
B1: 37272 | C1: 2002-01 | D1: 52120-7001-000-00 | E1: 52120 | F1: Parts and Materials Overhead Unal | G1: Repairs and Maint | H1: 7001 | I1: 12431.12
B3: Goal: | C3: Filter down to 2002-01 and any Description like Revenue -%
B5: {=_xll.jFilter(GLData!B3, AND(_xll.jWhere("Year Mth", "2002-01"), _xll.jWhere("Description", "%Other%", "LIKE")))} -> jFilter|Filtered!$B$5
B6: {=_xll.ReportRange(B5,B9:I10,B8:I8,B1:I1)} -> OK!: ReportRange Formula OK [jAction{}]
B7: Example: Filtered by Description
B8: Posted | C8: Year Mth | D8: Full Account | E8: Account | F8: Account Desc | G8: Description | H8: Dist | I8: Amount

Sheet Filtered2
B1: 37272 | C1: 2002-01 | D1: 52120-7001-000-00 | E1: 52120 | F1: Parts and Materials Overhead Unal | G1: Repairs and Maint | H1: 7001 | I1: 12431.12
B3: Goal: | C3: Filter on in-sheet parameters in jFilter's jWhere blocks (configurable)
E4: (change me)
B5: {=_xll.jFilter(GLData!B3, AND(_xll.jWhere("Account", F5, E5), _xll.jWhere("Dist", F6, E6)))} -> jFilter|Filtered2!$B$5 | D5: Account | E5: = | F5: 52120
D6: Dist | E6: = | F6: 7002
B7: {=_xll.ReportRange(B5,B10:I11,B9:I9,B1:I1)} -> OK!: ReportRange Formula OK [jAction{}]
B8: Example: Filtered by Description
B9: Posted | C9: Year Mth | D9: Full Account | E9: Account | F9: Account Desc | G9: Description | H9: Dist | I9: Amount

Sheet JoinDist
B1: 37272 | C1: 2002-01 | D1: 52120-7001-000-00 | E1: 52120 | F1: Parts and Materials Overhead Unal | G1: Repairs and Maint | H1: 59.46 | I1: 7001 | J1: Landfill
B3: Goal: | C3: Join the two tables in GLData on District
C5: {=_xll.jJoin(GLData!B3,GLData!B4,"INNER","Dist","Dist")} -> jJoin|JoinDist!$C$5 | E5: =jJoin(GLData!B3,GLData!B4,"INNER","Dist","Dist")
C6: {=_xll.jFilter(C5, _xll.jWhere("Description","Facility Expense"))} -> jFilter|JoinDist!$C$6 | E6: =jFilter(C5, jWhere("Description","Facility Expense"))
C8: {=_xll.ReportRange(C6,B11:J315,B10:J10,B1:J1)} -> OK!: ReportRange Formula OK [jAction{}]
B10: Posted | C10: Year Mth | D10: Full Account | E10: Account | F10: Account Desc | G10: Description | H10: Amount | I10: Dist | J10: Type
B11: 37272 | C11: 2002-01 | D11: 52150-7001-000-00 | E11: 52150 | F11: Utilities Overhead Unallocated | G11: Facility Expense | H11: 153.72 | I11: 7001 | J11: Landfill
B12: 37272 | C12: 2002-01 | D12: 52150-7001-000-00 | E12: 52150 | F12: Utilities Overhead Unallocated | G12: Facility Expense | H12: 201.23 | I12: 7001 | J12: Landfill
B13: 37272 | C13: 2002-01 | D13: 52165-7001-000-00 | E13: 52165 | F13: Communications Overhead Unallocat | G13: Facility Expense | H13: 97.2 | I13: 7001 | J13: Landfill
B14: 37272 | C14: 2002-01 | D14: 52200-7001-000-00 | E14: 52200 | F14: Office Supply and Equip Overhead | G14: Facility Expense | H14: 5.38 | I14: 7001 | J14: Landfill
B15: 37272 | C15: 2002-01 | D15: 52200-7002-000-00 | E15: 52200 | F15: Office Supply and Equip Overhea | G15: Facility Expense | H15: 15.75 | I15: 7002 | J15: Hauling
B16: 37272 | C16: 2002-01 | D16: 70147-7001-000-00 | E16: 70147 | F16: Bldg & Property Maint Overhead Un | G16: Facility Expense | H16: 40 | I16: 7001 | J16: Landfill
B17: 37272 | C17: 2002-01 | D17: 70165-7001-000-00 | E17: 70165 | F17: Communications Overhead Unallocat | G17: Facility Expense | H17: 64.6 | I17: 7001 | J17: Landfill
B18: 37272 | C18: 2002-01 | D18: 70165-7001-000-00 | E18: 70165 | F18: Communications Overhead Unallocat | G18: Facility Expense | H18: 21.6 | I18: 7001 | J18: Landfill
B19: 37274 | C19: 2002-01 | D19: 52200-7001-000-00 | E19: 52200 | F19: Office Supply and Equip Overhead | G19: Facility Expense | H19: 91 | I19: 7001 | J19: Landfill
B20: 37274 | C20: 2002-01 | D20: 52200-7001-000-00 | E20: 52200 | F20: Office Supply and Equip Overhead | G20: Facility Expense | H20: 251.49 | I20: 7001 | J20: Landfill
B21: 37278 | C21: 2002-01 | D21: 52165-7001-000-00 | E21: 52165 | F21: Communications Overhead Unallocat | G21: Facility Expense | H21: 118.86 | I21: 7001 | J21: Landfill
B22: 37278 | C22: 2002-01 | D22: 52200-7001-000-00 | E22: 52200 | F22: Office Supply and Equip Overhead | G22: Facility Expense | H22: 17.76 | I22: 7001 | J22: Landfill
... B314: 37407 | C314: 2002-05 | D314: 70165-7001-000-00 | E314: 70165 | F314: Communications Overhead Unallocat | G314: Facility Expense | H314: -112.90174 | I314: 7004 | J314: Landfill

Sheet Aggregate
B1: Revenue - Other | C1: 7001 | D1: 0
B3: Goal: | C3: Sum revenue across districts
B5: {=_xll.jFilter(GLData!B3, OR(_xll.jWhere(B10, "Revenue - Sales"), _xll.jWhere(B10, "Revenue - Other")))} -> jFilter|Aggregate!$B$5 | D5: =jFilter(GLData!B3, OR(jWhere(B10, "Revenue - Sales"), jWhere(B10, "Revenue - Other")))
B6: {=_xll.jQuery(B5, "SELECT Description, Dist, SUM(Amount) AS Total FROM @1 GROUP BY Description, Dist")} -> jQuery|Aggregate!$B$6 | D6: =jQuery(B5, "SELECT Description, Dist, SUM(Amount) AS Total FROM @1 GROUP BY Description, Dist")
B7: {=_xll.ReportRange(B6,B11:D19,B10:D10,B1:D1)} -> OK!: ReportRange Formula OK [jAction{}]
B9: Summary of Revenue and Other
B10: Description | C10: Dist | D10: Total
B11: Revenue - Other | C11: 7001 | D11: -33
B12: Revenue - Other | C12: 7002 | D12: -56062
B13: Revenue - Other | C13: 7004 | D13: -34
B14: Revenue - Other | C14: 7005 | D14: -56103
B15: Revenue - Sales | C15: 7001 | D15: -565973
B16: Revenue - Sales | C16: 7002 | D16: -356891
B17: Revenue - Sales | C17: 7004 | D17: -541657
B18: Revenue - Sales | C18: 7005 | D18: -345689

Sheet RevByType
B1: TEXT | C1: 12341.12
B3: Goal: | C3: Sum revenue across categories
B5: {=_xll.jQuery(GLData!B3, "SELECT * FROM @1 WHERE Description = 'Revenue - Sales' OR Description = 'Revenue - Other'")} -> jQuery|RevByType!$B$5 | D5: =jQuery(GLData!B3, "SELECT * FROM @1 WHERE Description = 'Revenue - Sales' OR Description = 'Revenue - Other'")
B6: {=_xll.jJoin(B5,GLData!B4,"INNER","Dist","Dist")} -> jJoin|RevByType!$B$6 | D6: =jJoin(B5,GLData!B4,"INNER","Dist","Dist")
B7: {=_xll.jQuery(B6, "SELECT Type, SUM(Amount) as Total FROM @1 GROUP BY Type ORDER BY Type DESC")} -> jQuery|RevByType!$B$7 | D7: =jQuery(B6, "SELECT Type, SUM(Amount) as Total FROM @1 GROUP BY Type ORDER BY Type DESC")
B8: {=_xll.ReportRange(B7,B11:C12,B10:C10,B1:C1)} -> OK!: ReportRange Formula OK [jAction{}]
B9: Total Rev by Dist Type
B10: Type | C10: Total
C13: =SUM(C11:C11) -> 0

Sheet GLDataRename
A1: RENAMING | C1: Year-Month | D1: Account2-Location-S3-S4
B2: Posted | C2: Year Mth | D2: Full Account | E2: Account | F2: Account Desc | H2: Description | I2: Dist | J2: Amount
B4: {=_xll.jDataSource(B20:J2805, B1:J2,,"GL_Detail")} -> jDataSource|GLDataRename!$B$4|GL_Detail | E4: =jDataSource(B25:J2810, B24:J24,,"GL_Detail")
B5: {=_xll.jDataSource(B10:C13, B9:C9,,"Dist_Types")} -> jDataSource|GLDataRename!$B$5|Dist_Types | E5: =jDataSource(B15:C18, B14:C14,,"Dist_Types")
B8: Dist Types In Sheet | E8: DIST Descs | F8: {=_xll.jQuery(GLDataRename!B4, "SELECT * FROM @1 GROUP BY Description")} -> jQuery|GLDataRename!$F$8
B9: Dist | C9: Type | F9: {=_xll.jDropdown(F8,,,_xll.PairGroup(_xll.Pair("Account",F12),_xll.Pair("Description",F13),_xll.Pair("Dist",F14)),"Description")} -> > jDropdown is ready for multi target.
B10: 7001 | C10: Landfill | F10: CLICK ME
B11: 7002 | C11: Hauling
B12: 7004 | C12: Landfill | E12: Account: | F12: 56142
B13: 7005 | C13: Hauling | E13: Desc: | F13: G&A
E14: Dist: | F14: 7001
B18: GL Detail Data In Sheet | I18: Total | J18: =SUBTOTAL(9,J20:J2808) -> -71374.001
B19: Posted | C19: Year Mth | D19: Full Account | E19: Account | F19: Account Desc | H19: Description | I19: Dist | J19: Amount | S19: Syst | T19: SubS | U19: Journal | V19: Journal Description | W19: Line Description
B20: 37272 | C20: 2002-01 | D20: 52120-7001-000-00 | E20: 52120 | F20: Parts and Materials Overhead Unal | H20: Repairs and Maint | I20: 7001 | J20: 50.12 | S20: 000 | T20: 00 | U20: JRNLWA00030958 | V20: From Voucher Posting. | W20: suas Auto adhuc
B21: 37272 | C21: 2002-01 | D21: 52120-7001-000-00 | E21: 52120 | F21: Parts and Materials Overhead Unal | H21: Repairs and Maint | I21: 7001 | J21: 59.46 | S21: 000 | T21: 00 | U21: JRNLWA00030958 | V21: From Voucher Posting. | W21: odio Auto audis
B22: 37272 | C22: 2002-01 | D22: 52120-7001-000-00 | E22: 52120 | F22: Parts and Materials Overhead Unal | H22: Repairs and Maint | I22: 7001 | J22: 17.71 | S22: 000 | T22: 00 | U22: JRNLWA00030958 | V22: From Voucher Posting. | W22: pede Auto dicit
B23: 37272 | C23: 2002-01 | D23: 52120-7001-000-00 | E23: 52120 | F23: Parts and Materials Overhead Unal | H23: Repairs and Maint | I23: 7001 | J23: 47.17 | S23: 000 | T23: 00 | U23: JRNLWA00030958 | V23: From Voucher Posting. | W23: City of Union vim
B24: 37272 | C24: 2002-01 | D24: 52125-7001-000-00 | E24: 52125 | F24: Operating Supplies Overhead Unall | H24: Repairs and Maint | I24: 7001 | J24: 55.04 | S24: 000 | T24: 00 | U24: JRNLWA00030958 | V24: From Voucher Posting. | W24: inquam inermis gravida Inc
B25: 37272 | C25: 2002-01 | D25: 52125-7001-000-00 | E25: 52125 | F25: Operating Supplies Overhead Unall | H25: Repairs and Maint | I25: 7001 | J25: 92.86 | S25: 000 | T25: 00 | U25: JRNLWA00030958 | V25: From Voucher Posting. | W25: ignota delenit debitis Inc
B26: 37272 | C26: 2002-01 | D26: 52125-7001-000-00 | E26: 52125 | F26: Operating Supplies Overhead Unall | H26: Repairs and Maint | I26: 7001 | J26: 42.64 | S26: 000 | T26: 00 | U26: JRNLWA00030958 | V26: From Voucher Posting. | W26: latine invidunt nam Auto massa
B27: 37272 | C27: 2002-01 | D27: 52142-7001-000-00 | E27: 52142 | F27: Fuel Expense Overhead Unallocated | H27: Repairs and Maint | I27: 7001 | J27: 12.66 | S27: 000 | T27: 00 | U27: JRNLWA00030958 | V27: From Voucher Posting. | W27: audiam quas
B28: 37272 | C28: 2002-01 | D28: 52150-7001-000-00 | E28: 52150 | F28: Utilities Overhead Unallocated | H28: Facility Expense | I28: 7001 | J28: 153.72 | S28: 000 | T28: 00 | U28: JRNLWA00030958 | V28: From Voucher Posting. | W28: labitur lacus
B29: 37272 | C29: 2002-01 | D29: 52150-7001-000-00 | E29: 52150 | F29: Utilities Overhead Unallocated | H29: Facility Expense | I29: 7001 | J29: 201.23 | S29: 000 | T29: 00 | U29: JRNLWA00030958 | V29: From Voucher Posting. | W29: blandit iacet
B30: 37272 | C30: 2002-01 | D30: 52165-7001-000-00 | E30: 52165 | F30: Communications Overhead Unallocat | H30: Facility Expense | I30: 7001 | J30: 97.2 | S30: 000 | T30: 00 | U30: JRNLWA00030958 | V30: From Voucher Posting. | W30: dicam saepius duo Inc
B31: 37272 | C31: 2002-01 | D31: 52200-7001-000-00 | E31: 52200 | F31: Office Supply and Equip Overhead | H31: Facility Expense | I31: 7001 | J31: 5.38 | S31: 000 | T31: 00 | U31: JRNLWA00030958 | V31: From Voucher Posting. | W31: delenit Washington ipsum belle
... B1412: 37407 | C1412: 2002-05 | D1412: 80099-7002-000-00 | E1412: 80099 | F1412: Interest Allocation Overhead Un | H1412: Interest Expense | I1412: 7002 | J1412: -695.12 | S1412: 000 | T1412: 00 | U1412: JRNLWA00035419 | V1412: Interest Allocation | W1412: Feb Interest Allocation
B1413: 37272 | C1413: 2002-01 | D1413: 52120-7001-000-00 | E1413: 52120 | F1413: Parts and Materials Overhead Unal | H1413: Repairs and Maint | I1413: 7004 | J1413: 47.40871 | S1413: 000 | T1413: 00
B1414: 37272 | C1414: 2002-01 | D1414: 52120-7001-000-00 | E1414: 52120 | F1414: Parts and Materials Overhead Unal | H1414: Repairs and Maint | I1414: 7004 | J1414: 63.898717 | S1414: 000 | T1414: 00
B1415: 37272 | C1415: 2002-01 | D1415: 52120-7001-000-00 | E1415: 52120 | F1415: Parts and Materials Overhead Unal | H1415: Repairs and Maint | I1415: 7004 | J1415: 20.171477 | S1415: 000 | T1415: 00
B1416: 37272 | C1416: 2002-01 | D1416: 52120-7001-000-00 | E1416: 52120 | F1416: Parts and Materials Overhead Unal | H1416: Repairs and Maint | I1416: 7004 | J1416: 52.103143 | S1416: 000 | T1416: 00
B1417: 37272 | C1417: 2002-01 | D1417: 52125-7001-000-00 | E1417: 52125 | F1417: Operating Supplies Overhead Unall | H1417: Repairs and Maint | I1417: 7004 | J1417: 53.285391 | S1417: 000 | T1417: 00
B1418: 37272 | C1418: 2002-01 | D1418: 52125-7001-000-00 | E1418: 52125 | F1418: Operating Supplies Overhead Unall | H1418: Repairs and Maint | I1418: 7004 | J1418: 98.482024 | S1418: 000 | T1418: 00
B1419: 37272 | C1419: 2002-01 | D1419: 52125-7001-000-00 | E1419: 52125 | F1419: Operating Supplies Overhead Unall | H1419: Repairs and Maint | I1419: 7004 | J1419: 35.410978 | S1419: 000 | T1419: 00
B1420: 37272 | C1420: 2002-01 | D1420: 52142-7001-000-00 | E1420: 52142 | F1420: Fuel Expense Overhead Unallocated | H1420: Repairs and Maint | I1420: 7004 | J1420: 15.107386 | S1420: 000 | T1420: 00
B1421: 37272 | C1421: 2002-01 | D1421: 52150-7001-000-00 | E1421: 52150 | F1421: Utilities Overhead Unallocated | H1421: Facility Expense | I1421: 7004 | J1421: 144.68466 | S1421: 000 | T1421: 00
B1422: 37272 | C1422: 2002-01 | D1422: 52150-7001-000-00 | E1422: 52150 | F1422: Utilities Overhead Unallocated | H1422: Facility Expense | I1422: 7004 | J1422: 231.44271 | S1422: 000 | T1422: 00
B1423: 37272 | C1423: 2002-01 | D1423: 52165-7001-000-00 | E1423: 52165 | F1423: Communications Overhead Unallocat | H1423: Facility Expense | I1423: 7004 | J1423: 111.63661 | S1423: 000 | T1423: 00
B1424: 37272 | C1424: 2002-01 | D1424: 52200-7001-000-00 | E1424: 52200 | F1424: Office Supply and Equip Overhead | H1424: Facility Expense | I1424: 7004 | J1424: 5.3110801 | S1424: 000 | T1424: 00
... B2805: 37407 | C2805: 2002-05 | D2805: 80099-7002-000-00 | E2805: 80099 | F2805: Interest Allocation Overhead Un | H2805: Interest Expense | I2805: 7005 | J2805: -691.21402 | S2805: 000 | T2805: 00
B2808: End of List
...

Sheet PullRename
B2: Goal: | C2: Show jDataSource renaming and splitting of columns.
B4: {=_xll.ReportRange(GLDataRename!B4,B6:J7,B5:J5,B1:J1)} -> OK!: ReportRange Formula OK [jAction{}]
B5: Posted | C5: Year | D5: Month | E5: Location | F5: Account | G5: Account Desc | H5: Description | I5: Dist | J5: Amount

Sheet Full GL Data
B1: GL Data
E2: Total: | F2: =SUM(F5:F1399) -> -72301.91
E3: Row Count: | F3: =COUNT(F5:F1399) -> 1393
B4: Date | C4: Year Mth | D4: Full Account | E4: Account Desc | F4: Amount | G4: Journal | H4: Journal Description | I4: Line Description | J4: User | K4: Status | L4: Trx Type Code | M4: Account | N4: Account Type | O4: Type Description | P4: Dist | Q4: Syst | R4: Subs | S4: Hold Flag | T4: Document 2 | U4: Document 1 | V4: Vendor Code | W4: Doc Ctrl Num | X4: Date Doc | Y4: Date Due | Z4: Doc Desc | AA4: PO Ctrl Num | AB4: Vend Order Num | AC4: Ticket Num | AD4: Class Code | AE4: Amount Net | AF4: Database | AG4: Company | AH4: Orig Company | AI4: Currency | AJ4: Nat Amount | AK4: Sequence ID | AL4: Reversing Flag | AM4: Recurring Flag | AN4: Repeating Flag | AO4: Type Flag | AP4: Posted | AQ4: Date Entered | AR4: Date Posted | AS4: Posted Flag | AT4: Raw Account | AU4: VO Number Drill
B5: 37272 | C5: 2002-01 | D5: 52120-7001-000-00 | E5: Parts and Materials Overhead Unal | F5: 50.12 | G5: JRNLWA00030958 | H5: From Voucher Posting. | I5: suas Auto adhuc | J5: Jsmith | K5: Posted | L5: JE IC | M5: 52120 | N5: 458 | O5: Repairs and Maint | P5: 7001 | Q5: 000 | R5: 00 | S5: FALSE | T5: VO00457136 | U5: JRNL00078609 | V5: VEND1217 | W5: 062746 | X5: 37264 | Y5: 37321 | AD5: 7001 | AE5: 50.12 | AF5: ERP_Demo | AG5: ERP_Demo | AI5: USD | AJ5: 50.12 | AK5: 1 | AL5: FALSE | AM5: FALSE | AN5: FALSE | AO5: 0 | AP5: 1 | AQ5: 37272 | AR5: 37284 | AS5: 1 | AT5: 52120700100000 | AU5: =IF(LEFT(T5,2)="VO",T5,"") -> VO00457136
B6: 37272 | C6: 2002-01 | D6: 52120-7001-000-00 | E6: Parts and Materials Overhead Unal | F6: 59.46 | G6: JRNLWA00030958 | H6: From Voucher Posting. | I6: odio Auto audis | J6: Jsmith | K6: Posted | L6: JE IC | M6: 52120 | N6: 458 | O6: Repairs and Maint | P6: 7001 | Q6: 000 | R6: 00 | S6: FALSE | T6: VO00457137 | U6: JRNL00078609 | V6: VEND1217 | W6: 294272 | X6: 37267 | Y6: 37324 | AD6: 7001 | AE6: 59.46 | AF6: ERP_Demo | AG6: ERP_Demo | AI6: USD | AJ6: 59.46 | AK6: 2 | AL6: FALSE | AM6: FALSE | AN6: FALSE | AO6: 0 | AP6: 1 | AQ6: 37272 | AR6: 37284 | AS6: 1 | AT6: 52120700100000 | AU6: =IF(LEFT(T6,2)="VO",T6,"") -> VO00457137
B7: 37272 | C7: 2002-01 | D7: 52120-7001-000-00 | E7: Parts and Materials Overhead Unal | F7: 17.71 | G7: JRNLWA00030958 | H7: From Voucher Posting. | I7: pede Auto dicit | J7: Jsmith | K7: Posted | L7: JE IC | M7: 52120 | N7: 458 | O7: Repairs and Maint | P7: 7001 | Q7: 000 | R7: 00 | S7: FALSE | T7: VO00457138 | U7: JRNL00078609 | V7: VEND1217 | W7: 620120 | X7: 37266 | Y7: 37323 | AD7: 7001 | AE7: 17.71 | AF7: ERP_Demo | AG7: ERP_Demo | AI7: USD | AJ7: 17.71 | AK7: 3 | AL7: FALSE | AM7: FALSE | AN7: FALSE | AO7: 0 | AP7: 1 | AQ7: 37272 | AR7: 37284 | AS7: 1 | AT7: 52120700100000 | AU7: =IF(LEFT(T7,2)="VO",T7,"") -> VO00457138
B8: 37272 | C8: 2002-01 | D8: 52120-7001-000-00 | E8: Parts and Materials Overhead Unal | F8: 47.17 | G8: JRNLWA00030958 | H8: From Voucher Posting. | I8: City of Union vim | J8: Jsmith | K8: Posted | L8: JE IC | M8: 52120 | N8: 458 | O8: Repairs and Maint | P8: 7001 | Q8: 000 | R8: 00 | S8: FALSE | T8: VO00457158 | U8: JRNL00078609 | V8: VEND1143 | W8: 133446-817 | X8: 37246 | Y8: 37256 | AD8: 7001 | AE8: 47.17 | AF8: ERP_Demo | AG8: ERP_Demo | AI8: USD | AJ8: 47.17 | AK8: 17 | AL8: FALSE | AM8: FALSE | AN8: FALSE | AO8: 0 | AP8: 1 | AQ8: 37272 | AR8: 37284 | AS8: 1 | AT8: 52120700100000 | AU8: =IF(LEFT(T8,2)="VO",T8,"") -> VO00457158
B9: 37272 | C9: 2002-01 | D9: 52125-7001-000-00 | E9: Operating Supplies Overhead Unall | F9: 55.04 | G9: JRNLWA00030958 | H9: From Voucher Posting. | I9: inquam inermis gravida Inc | J9: Jsmith | K9: Posted | L9: JE IC | M9: 52125 | N9: 458 | O9: Repairs and Maint | P9: 7001 | Q9: 000 | R9: 00 | S9: FALSE | T9: VO00457156 | U9: JRNL00078609 | V9: VEND1290 | W9: 322869 | X9: 37243 | Y9: 37300 | AD9: 7001 | AE9: 55.04 | AF9: ERP_Demo | AG9: ERP_Demo | AI9: USD | AJ9: 55.04 | AK9: 15 | AL9: FALSE | AM9: FALSE | AN9: FALSE | AO9: 0 | AP9: 1 | AQ9: 37272 | AR9: 37284 | AS9: 1 | AT9: 52125700100000 | AU9: =IF(LEFT(T9,2)="VO",T9,"") -> VO00457156
B10: 37272 | C10: 2002-01 | D10: 52125-7001-000-00 | E10: Operating Supplies Overhead Unall | F10: 92.86 | G10: JRNLWA00030958 | H10: From Voucher Posting. | I10: ignota delenit debitis Inc | J10: Jsmith | K10: Posted | L10: JE IC | M10: 52125 | N10: 458 | O10: Repairs and Maint | P10: 7001 | Q10: 000 | R10: 00 | S10: FALSE | T10: VO00457157 | U10: JRNL00078609 | V10: VEND1290 | W10: 580089 | X10: 37254 | Y10: 37311 | AD10: 7001 | AE10: 92.86 | AF10: ERP_Demo | AG10: ERP_Demo | AI10: USD | AJ10: 92.86 | AK10: 16 | AL10: FALSE | AM10: FALSE | AN10: FALSE | AO10: 0 | AP10: 1 | AQ10: 37272 | AR10: 37284 | AS10: 1 | AT10: 52125700100000 | AU10: =IF(LEFT(T10,2)="VO",T10,"") -> VO00457157
B11: 37272 | C11: 2002-01 | D11: 52125-7001-000-00 | E11: Operating Supplies Overhead Unall | F11: 42.64 | G11: JRNLWA00030958 | H11: From Voucher Posting. | I11: latine invidunt nam Auto massa | J11: Jsmith | K11: Posted | L11: JE IC | M11: 52125 | N11: 458 | O11: Repairs and Maint | P11: 7001 | Q11: 000 | R11: 00 | S11: FALSE | T11: VO00457140 | U11: JRNL00078609 | V11: VEND1288 | W11: 144306 | X11: 37266 | Y11: 37323 | AD11: 7001 | AE11: 42.64 | AF11: ERP_Demo | AG11: ERP_Demo | AI11: USD | AJ11: 42.64 | AK11: 5 | AL11: FALSE | AM11: FALSE | AN11: FALSE | AO11: 0 | AP11: 1 | AQ11: 37272 | AR11: 37284 | AS11: 1 | AT11: 52125700100000 | AU11: =IF(LEFT(T11,2)="VO",T11,"") -> VO00457140
B12: 37272 | C12: 2002-01 | D12: 52142-7001-000-00 | E12: Fuel Expense Overhead Unallocated | F12: 12.66 | G12: JRNLWA00030958 | H12: From Voucher Posting. | I12: audiam quas | J12: Jsmith | K12: Posted | L12: JE IC | M12: 52142 | N12: 458 | O12: Repairs and Maint | P12: 7001 | Q12: 000 | R12: 00 | S12: FALSE | T12: VO00457142 | U12: JRNL00078609 | V12: VEND1287 | W12: 1-11-02 | X12: 37267 | Y12: 37324 | AD12: 7001 | AE12: 12.66 | AF12: ERP_Demo | AG12: ERP_Demo | AI12: USD | AJ12: 12.66 | AK12: 7 | AL12: FALSE | AM12: FALSE | AN12: FALSE | AO12: 0 | AP12: 1 | AQ12: 37272 | AR12: 37284 | AS12: 1 | AT12: 52142700100000 | AU12: =IF(LEFT(T12,2)="VO",T12,"") -> VO00457142
B13: 37272 | C13: 2002-01 | D13: 52150-7001-000-00 | E13: Utilities Overhead Unallocated | F13: 153.72 | G13: JRNLWA00030958 | H13: From Voucher Posting. | I13: labitur lacus | J13: Jsmith | K13: Posted | L13: JE IC | M13: 52150 | N13: 459 | O13: Facility Expense | P13: 7001 | Q13: 000 | R13: 00 | S13: FALSE | T13: VO00457146 | U13: JRNL00078609 | V13: VEND1226 | W13: 82698304-056 7 | X13: 37258 | Y13: 37268 | AD13: 7001 | AE13: 153.72 | AF13: ERP_Demo | AG13: ERP_Demo | AI13: USD | AJ13: 153.72 | AK13: 10 | AL13: FALSE | AM13: FALSE | AN13: FALSE | AO13: 0 | AP13: 1 | AQ13: 37272 | AR13: 37284 | AS13: 1 | AT13: 52150700100000 | AU13: =IF(LEFT(T13,2)="VO",T13,"") -> VO00457146
B14: 37272 | C14: 2002-01 | D14: 52150-7001-000-00 | E14: Utilities Overhead Unallocated | F14: 201.23 | G14: JRNLWA00030958 | H14: From Voucher Posting. | I14: blandit iacet | J14: Jsmith | K14: Posted | L14: JE IC | M14: 52150 | N14: 459 | O14: Facility Expense | P14: 7001 | Q14: 000 | R14: 00 | S14: FALSE | T14: VO00457147 | U14: JRNL00078609 | V14: VEND1226 | W14: 18908583-842 9 | X14: 37258 | Y14: 37268 | AD14: 7001 | AE14: 201.23 | AF14: ERP_Demo | AG14: ERP_Demo | AI14: USD | AJ14: 201.23 | AK14: 11 | AL14: FALSE | AM14: FALSE | AN14: FALSE | AO14: 0 | AP14: 1 | AQ14: 37272 | AR14: 37284 | AS14: 1 | AT14: 52150700100000 | AU14: =IF(LEFT(T14,2)="VO",T14,"") -> VO00457147
B15: 37272 | C15: 2002-01 | D15: 52165-7001-000-00 | E15: Communications Overhead Unallocat | F15: 97.2 | G15: JRNLWA00030958 | H15: From Voucher Posting. | I15: dicam saepius duo Inc | J15: Jsmith | K15: Posted | L15: JE IC | M15: 52165 | N15: 459 | O15: Facility Expense | P15: 7001 | Q15: 000 | R15: 00 | S15: FALSE | T15: VO00457154 | U15: JRNL00078609 | V15: VEND1240 | W15: COTIDIEQUE | X15: 37256 | Y15: 37286 | AD15: 7001 | AE15: 97.2 | AF15: ERP_Demo | AG15: ERP_Demo | AI15: USD | AJ15: 97.2 | AK15: 13 | AL15: FALSE | AM15: FALSE | AN15: FALSE | AO15: 0 | AP15: 1 | AQ15: 37272 | AR15: 37284 | AS15: 1 | AT15: 52165700100000 | AU15: =IF(LEFT(T15,2)="VO",T15,"") -> VO00457154
B16: 37272 | C16: 2002-01 | D16: 52200-7001-000-00 | E16: Office Supply and Equip Overhead | F16: 5.38 | G16: JRNLWA00030958 | H16: From Voucher Posting. | I16: delenit Washington ipsum belle | J16: Jsmith | K16: Posted | L16: JE IC | M16: 52200 | N16: 459 | O16: Facility Expense | P16: 7001 | Q16: 000 | R16: 00 | S16: FALSE | T16: VO00457165 | U16: JRNL00078609 | V16: VEND1134 | W16: 390294 | X16: 37260 | Y16: 37270 | AD16: 7001 | AE16: 5.38 | AF16: ERP_Demo | AG16: ERP_Demo | AI16: USD | AJ16: 5.38 | AK16: 18 | AL16: FALSE | AM16: FALSE | AN16: FALSE | AO16: 0 | AP16: 1 | AQ16: 37272 | AR16: 37284 | AS16: 1 | AT16: 52200700100000 | AU16: =IF(LEFT(T16,2)="VO",T16,"") -> VO00457165
... B40: 37279 | C40: 2002-01 | D40: 52170-7002-000-00 | E40: Real Estate Rentals Overhead Un | F40: 1090 | G40: JRNLWA00031028 | H40: From Voucher Posting. | I40: a a summus Inc | J40: Jsmith | K40: Posted | L40: JE IC | M40: 52170 | N40: 459 | O40: Facility Expense | P40: 7002 | Q40: 000 | R40: 00 | S40: FALSE | T40: VO00462164 | U40: JRNL00079091 | V40: VEND1267 | W40: 02-9-02 RENT | X40: 37276 | Y40: 37286 | AD40: 1000 | AE40: 1090 | AF40: ERP_Demo | AG40: ERP_Demo | AI40: USD | AJ40: 1090 | AK40: 24 | AL40: FALSE | AM40: FALSE | AN40: FALSE | AO40: 0 | AP40: 1 | AQ40: 37279 | AR40: 37284 | AS40: 1 | AT40: 52170700200000 | AU40: =IF(LEFT(T40,2)="VO",T40,"") -> VO00462164
B41: 37281 | C41: 2002-01 | D41: 50020-7002-000-00 | E41: Wages Regular Overhead Unalloca | F41: 2835.59 | G41: JRNLWA00030908 | H41: Payroll P-E 1-40-02 | I41: Payroll a-a 1-51-02 | J41: Bsmith | K41: Posted | L41: JE STD | M41: 50020 | N41: 456 | O41: Salary and Wages | P41: 7002 | Q41: 000 | R41: 00 | S41: FALSE | T41: JRNLWA00030908 | X41: 2 | Y41: 2 | AE41: 0 | AF41: ERP_Demo | AG41: ERP_Demo | AI41: USD | AJ41: 2835.59 | AK41: 2 | AL41: FALSE | AM41: FALSE | AN41: FALSE | AO41: 0 | AP41: 1 | AQ41: 37281 | AR41: 37284 | AS41: 1 | AT41: 50020700200000 | AU41: =IF(LEFT(T41,2)="VO",T41,"")
B42: 37281 | C42: 2002-01 | D42: 50020-7002-000-00 | E42: Wages Regular Overhead Unalloca | F42: 1118.16 | G42: JRNLWA00030908 | H42: Payroll P-E 1-40-02 | I42: Payroll a-a 1-97-02 | J42: Bsmith | K42: Posted | L42: JE STD | M42: 50020 | N42: 456 | O42: Salary and Wages | P42: 7002 | Q42: 000 | R42: 00 | S42: FALSE | T42: JRNLWA00030908 | X42: 2 | Y42: 2 | AE42: 0 | AF42: ERP_Demo | AG42: ERP_Demo | AI42: USD | AJ42: 1118.16 | AK42: 3 | AL42: FALSE | AM42: FALSE | AN42: FALSE | AO42: 0 | AP42: 1 | AQ42: 37281 | AR42: 37284 | AS42: 1 | AT42: 50020700200000 | AU42: =IF(LEFT(T42,2)="VO",T42,"")
B43: 37281 | C43: 2002-01 | D43: 50025-7002-000-00 | E43: Wages O.T. Overhead Unallocated | F43: 101.25 | G43: JRNLWA00030908 | H43: Payroll P-E 1-40-02 | I43: Payroll a-a 1-34-02 | J43: Bsmith | K43: Posted | L43: JE STD | M43: 50025 | N43: 456 | O43: Salary and Wages | P43: 7002 | Q43: 000 | R43: 00 | S43: FALSE | T43: JRNLWA00030908 | X43: 2 | Y43: 2 | AE43: 0 | AF43: ERP_Demo | AG43: ERP_Demo | AI43: USD | AJ43: 101.25 | AK43: 5 | AL43: FALSE | AM43: FALSE | AN43: FALSE | AO43: 0 | AP43: 1 | AQ43: 37281 | AR43: 37284 | AS43: 1 | AT43: 50025700200000 | AU43: =IF(LEFT(T43,2)="VO",T43,"")
B44: 37281 | C44: 2002-01 | D44: 50050-7002-000-00 | E44: Payroll Taxes Overhead Unalloca | F44: 260.92 | G44: JRNLWA00030908 | H44: Payroll P-E 1-40-02 | I44: Payroll a-a 1-66-02 | J44: Bsmith | K44: Posted | L44: JE STD | M44: 50050 | N44: 456 | O44: Salary and Wages | P44: 7002 | Q44: 000 | R44: 00 | S44: FALSE | T44: JRNLWA00030908 | X44: 2 | Y44: 2 | AE44: 0 | AF44: ERP_Demo | AG44: ERP_Demo | AI44: USD | AJ44: 260.92 | AK44: 7 | AL44: FALSE | AM44: FALSE | AN44: FALSE | AO44: 0 | AP44: 1 | AQ44: 37281 | AR44: 37284 | AS44: 1 | AT44: 50050700200000 | AU44: =IF(LEFT(T44,2)="VO",T44,"")
B45: 37281 | C45: 2002-01 | D45: 50050-7002-000-00 | E45: Payroll Taxes Overhead Unalloca | F45: 111.05 | G45: JRNLWA00030908 | H45: Payroll P-E 1-40-02 | I45: Payroll a-a 1-05-02 | J45: Bsmith | K45: Posted | L45: JE STD | M45: 50050 | N45: 456 | O45: Salary and Wages | P45: 7002 | Q45: 000 | R45: 00 | S45: FALSE | T45: JRNLWA00030908 | X45: 2 | Y45: 2 | AE45: 0 | AF45: ERP_Demo | AG45: ERP_Demo | AI45: USD | AJ45: 111.05 | AK45: 8 | AL45: FALSE | AM45: FALSE | AN45: FALSE | AO45: 0 | AP45: 1 | AQ45: 37281 | AR45: 37284 | AS45: 1 | AT45: 50050700200000 | AU45: =IF(LEFT(T45,2)="VO",T45,"")
B46: 37281 | C46: 2002-01 | D46: 50060-7002-000-00 | E46: Group Insurance Overhead Unallo | F46: -98.5 | G46: JRNLWA00030908 | H46: Payroll P-E 1-40-02 | I46: Payroll a-a 1-90-02 | J46: Bsmith | K46: Posted | L46: JE STD | M46: 50060 | N46: 457 | O46: Benefits | P46: 7002 | Q46: 000 | R46: 00 | S46: FALSE | T46: JRNLWA00030908 | X46: 2 | Y46: 2 | AE46: 0 | AF46: ERP_Demo | AG46: ERP_Demo | AI46: USD | AJ46: -98.5 | AK46: 10 | AL46: FALSE | AM46: FALSE | AN46: FALSE | AO46: 0 | AP46: 1 | AQ46: 37281 | AR46: 37284 | AS46: 1 | AT46: 50060700200000 | AU46: =IF(LEFT(T46,2)="VO",T46,"")
B47: 37281 | C47: 2002-01 | D47: 50065-7002-000-00 | E47: Vacation Pay Overhead Unallocat | F47: 124.24 | G47: JRNLWA00030908 | H47: Payroll P-E 1-40-02 | I47: Payroll a-a 1-60-02 | J47: Bsmith | K47: Posted | L47: JE STD | M47: 50065 | N47: 457 | O47: Benefits | P47: 7002 | Q47: 000 | R47: 00 | S47: FALSE | T47: JRNLWA00030908 | X47: 2 | Y47: 2 | AE47: 0 | AF47: ERP_Demo | AG47: ERP_Demo | AI47: USD | AJ47: 124.24 | AK47: 4 | AL47: FALSE | AM47: FALSE | AN47: FALSE | AO47: 0 | AP47: 1 | AQ47: 37281 | AR47: 37284 | AS47: 1 | AT47: 50065700200000 | AU47: =IF(LEFT(T47,2)="VO",T47,"")
B48: 37281 | C48: 2002-01 | D48: 52020-7002-000-00 | E48: Wages Regular Overhead Unalloca | F48: 816.38 | G48: JRNLWA00030908 | H48: Payroll P-E 1-40-02 | I48: Payroll a-a 1-28-02 | J48: Bsmith | K48: Posted | L48: JE STD | M48: 52020 | N48: 456 | O48: Salary and Wages | P48: 7002 | Q48: 000 | R48: 00 | S48: FALSE | T48: JRNLWA00030908 | X48: 2 | Y48: 2 | AE48: 0 | AF48: ERP_Demo | AG48: ERP_Demo | AI48: USD | AJ48: 816.38 | AK48: 1 | AL48: FALSE | AM48: FALSE | AN48: FALSE | AO48: 0 | AP48: 1 | AQ48: 37281 | AR48: 37284 | AS48: 1 | AT48: 52020700200000 | AU48: =IF(LEFT(T48,2)="VO",T48,"")
B49: 37281 | C49: 2002-01 | D49: 52050-7002-000-00 | E49: Payroll Taxes Overhead Unalloca | F49: 71.82 | G49: JRNLWA00030908 | H49: Payroll P-E 1-40-02 | I49: Payroll a-a 1-59-02 | J49: Bsmith | K49: Posted | L49: JE STD | M49: 52050 | N49: 456 | O49: Salary and Wages | P49: 7002 | Q49: 000 | R49: 00 | S49: FALSE | T49: JRNLWA00030908 | X49: 2 | Y49: 2 | AE49: 0 | AF49: ERP_Demo | AG49: ERP_Demo | AI49: USD | AJ49: 71.82 | AK49: 6 | AL49: FALSE | AM49: FALSE | AN49: FALSE | AO49: 0 | AP49: 1 | AQ49: 37281 | AR49: 37284 | AS49: 1 | AT49: 52050700200000 | AU49: =IF(LEFT(T49,2)="VO",T49,"")
B50: 37281 | C50: 2002-01 | D50: 52125-7001-000-00 | E50: Operating Supplies Overhead Unall | F50: 62.73 | G50: JRNLWA00031039 | H50: From Voucher Posting. | I50: consul maximus ratione Inc | J50: Cbalderas | K50: Posted | L50: JE IC | M50: 52125 | N50: 458 | O50: Repairs and Maint | P50: 7001 | Q50: 000 | R50: 00 | S50: FALSE | T50: VO00462035 | U50: JRNL00079113 | V50: VEND1290 | W50: 10097 | X50: 37196 | Y50: 37253 | AD50: 7001 | AE50: 62.73 | AF50: ERP_Demo | AG50: ERP_Demo | AI50: USD | AJ50: 62.73 | AK50: 3 | AL50: FALSE | AM50: FALSE | AN50: FALSE | AO50: 0 | AP50: 1 | AQ50: 37281 | AR50: 37286 | AS50: 1 | AT50: 52125700100000 | AU50: =IF(LEFT(T50,2)="VO",T50,"") -> VO00462035
B51: 37281 | C51: 2002-01 | D51: 52142-7001-000-00 | E51: Fuel Expense Overhead Unallocated | F51: 656.5 | G51: JRNLWA00031039 | H51: From Voucher Posting. | I51: oportere duis Inc. | J51: Cbalderas | K51: Posted | L51: JE IC | M51: 52142 | N51: 458 | O51: Repairs and Maint | P51: 7001 | Q51: 000 | R51: 00 | S51: FALSE | T51: VO00462042 | U51: JRNL00079113 | V51: VEND1212 | W51: 73827 | X51: 37201 | Y51: 37221 | AD51: 7001 | AE51: 656.5 | AF51: ERP_Demo | AG51: ERP_Demo | AI51: USD | AJ51: 656.5 | AK51: 5 | AL51: FALSE | AM51: FALSE | AN51: FALSE | AO51: 0 | AP51: 1 | AQ51: 37281 | AR51: 37286 | AS51: 1 | AT51: 52142700100000 | AU51: =IF(LEFT(T51,2)="VO",T51,"") -> VO00462042
B52: 37281 | C52: 2002-01 | D52: 52165-7001-000-00 | E52: Communications Overhead Unallocat | F52: 50.17 | G52: JRNLWA00031039 | H52: From Voucher Posting. | I52: mauris | J52: Cbalderas | K52: Posted | L52: JE IC | M52: 52165 | N52: 459 | O52: Facility Expense | P52: 7001 | Q52: 000 | R52: 00 | S52: FALSE | T52: VO00462019 | U52: JRNL00079113 | V52: VEND1254 | W52: 781-038-7682-180 | X52: 37262 | Y52: 37272 | AD52: 7001 | AE52: 50.17 | AF52: ERP_Demo | AG52: ERP_Demo | AI52: USD | AJ52: 50.17 | AK52: 1 | AL52: FALSE | AM52: FALSE | AN52: FALSE | AO52: 0 | AP52: 1 | AQ52: 37281 | AR52: 37286 | AS52: 1 | AT52: 52165700100000 | AU52: =IF(LEFT(T52,2)="VO",T52,"") -> VO00462019
B53: 37281 | C53: 2002-01 | D53: 52165-7001-000-00 | E53: Communications Overhead Unallocat | F53: 20.09 | G53: JRNLWA00031039 | H53: From Voucher Posting. | I53: corrumpit | J53: Cbalderas | K53: Posted | L53: JE IC | M53: 52165 | N53: 459 | O53: Facility Expense | P53: 7001 | Q53: 000 | R53: 00 | S53: FALSE | T53: VO00462027 | U53: JRNL00079113 | V53: VEND1205 | W53: 5677447 | X53: 37275 | Y53: 37285 | AD53: 7001 | AE53: 20.09 | AF53: ERP_Demo | AG53: ERP_Demo | AI53: USD | AJ53: 20.09 | AK53: 2 | AL53: FALSE | AM53: FALSE | AN53: FALSE | AO53: 0 | AP53: 1 | AQ53: 37281 | AR53: 37286 | AS53: 1 | AT53: 52165700100000 | AU53: =IF(LEFT(T53,2)="VO",T53,"") -> VO00462027
B54: 37281 | C54: 2002-01 | D54: 70165-7001-000-00 | E54: Communications Overhead Unallocat | F54: 52.75 | G54: JRNLWA00031039 | H54: From Voucher Posting. | I54: no wisi necessitatibus | J54: Cbalderas | K54: Posted | L54: JE IC | M54: 70165 | N54: 459 | O54: Facility Expense | P54: 7001 | Q54: 000 | R54: 00 | S54: FALSE | T54: VO00462039 | U54: JRNL00079113 | V54: VEND1275 | W54: 009-TAM-4160 653 | X54: 37257 | Y54: 37267 | AD54: 7001 | AE54: 52.75 | AF54: ERP_Demo | AG54: ERP_Demo | AI54: USD | AJ54: 52.75 | AK54: 4 | AL54: FALSE | AM54: FALSE | AN54: FALSE | AO54: 0 | AP54: 1 | AQ54: 37281 | AR54: 37286 | AS54: 1 | AT54: 70165700100000 | AU54: =IF(LEFT(T54,2)="VO",T54,"") -> VO00462039
B55: 37284 | C55: 2002-01 | D55: 52120-7001-000-00 | E55: Parts and Materials Overhead Unal | F55: 48.32 | G55: JRNLWA00031047 | H55: From Voucher Posting. | I55: dissentiet erant | J55: Cbalderas | K55: Posted | L55: JE IC | M55: 52120 | N55: 458 | O55: Repairs and Maint | P55: 7001 | Q55: 000 | R55: 00 | S55: FALSE | T55: VO00462690 | U55: JRNL00079238 | V55: VEND1283 | W55: 8378205877 | X55: 37270 | Y55: 37327 | AD55: 7001 | AE55: 48.32 | AF55: ERP_Demo | AG55: ERP_Demo | AI55: USD | AJ55: 48.32 | AK55: 14 | AL55: FALSE | AM55: FALSE | AN55: FALSE | AO55: 0 | AP55: 1 | AQ55: 37284 | AR55: 37286 | AS55: 1 | AT55: 52120700100000 | AU55: =IF(LEFT(T55,2)="VO",T55,"") -> VO00462690
B56: 37284 | C56: 2002-01 | D56: 52120-7001-000-00 | E56: Parts and Materials Overhead Unal | F56: 101.32 | G56: JRNLWA00031047 | H56: From Voucher Posting. | I56: tritani idque verterem Inc | J56: Cbalderas | K56: Posted | L56: JE IC | M56: 52120 | N56: 458 | O56: Repairs and Maint | P56: 7001 | Q56: 000 | R56: 00 | S56: FALSE | T56: VO00462696 | U56: JRNL00079238 | V56: VEND1177 | W56: 621356 | X56: 37266 | Y56: 37323 | AD56: 7001 | AE56: 101.32 | AF56: ERP_Demo | AG56: ERP_Demo | AI56: USD | AJ56: 101.32 | AK56: 15 | AL56: FALSE | AM56: FALSE | AN56: FALSE | AO56: 0 | AP56: 1 | AQ56: 37284 | AR56: 37286 | AS56: 1 | AT56: 52120700100000 | AU56: =IF(LEFT(T56,2)="VO",T56,"") -> VO00462696
B57: 37284 | C57: 2002-01 | D57: 52120-7001-000-00 | E57: Parts and Materials Overhead Unal | F57: 30.46 | G57: JRNLWA00031047 | H57: From Voucher Posting. | I57: egestas idque officiis Inc | J57: Cbalderas | K57: Posted | L57: JE IC | M57: 52120 | N57: 458 | O57: Repairs and Maint | P57: 7001 | Q57: 000 | R57: 00 | S57: FALSE | T57: VO00462702 | U57: JRNL00079238 | V57: VEND1177 | W57: 127588 | X57: 37265 | Y57: 37322 | AD57: 7001 | AE57: 30.46 | AF57: ERP_Demo | AG57: ERP_Demo | AI57: USD | AJ57: 30.46 | AK57: 16 | AL57: FALSE | AM57: FALSE | AN57: FALSE | AO57: 0 | AP57: 1 | AQ57: 37284 | AR57: 37286 | AS57: 1 | AT57: 52120700100000 | AU57: =IF(LEFT(T57,2)="VO",T57,"") -> VO00462702
B58: 37284 | C58: 2002-01 | D58: 52120-7001-000-00 | E58: Parts and Materials Overhead Unal | F58: 29.75 | G58: JRNLWA00031047 | H58: From Voucher Posting. | I58: leo gloriatur Inc | J58: Cbalderas | K58: Posted | L58: JE IC | M58: 52120 | N58: 458 | O58: Repairs and Maint | P58: 7001 | Q58: 000 | R58: 00 | S58: FALSE | T58: VO00462705 | U58: JRNL00079238 | V58: VEND1249 | W58: 3-095773 | X58: 37266 | Y58: 37323 | AD58: 7001 | AE58: 29.75 | AF58: ERP_Demo | AG58: ERP_Demo | AI58: USD | AJ58: 29.75 | AK58: 17 | AL58: FALSE | AM58: FALSE | AN58: FALSE | AO58: 0 | AP58: 1 | AQ58: 37284 | AR58: 37286 | AS58: 1 | AT58: 52120700100000 | AU58: =IF(LEFT(T58,2)="VO",T58,"") -> VO00462705
B59: 37284 | C59: 2002-01 | D59: 52120-7001-000-00 | E59: Parts and Materials Overhead Unal | F59: 3.01 | G59: JRNLWA00031047 | H59: From Voucher Posting. | I59: iure Auto simul | J59: Cbalderas | K59: Posted | L59: JE IC | M59: 52120 | N59: 458 | O59: Repairs and Maint | P59: 7001 | Q59: 000 | R59: 00 | S59: FALSE | T59: VO00462649 | U59: JRNL00079238 | V59: VEND1217 | W59: 675682 | X59: 37272 | Y59: 37329 | AD59: 7001 | AE59: 3.01 | AF59: ERP_Demo | AG59: ERP_Demo | AI59: USD | AJ59: 3.01 | AK59: 6 | AL59: FALSE | AM59: FALSE | AN59: FALSE | AO59: 0 | AP59: 1 | AQ59: 37284 | AR59: 37286 | AS59: 1 | AT59: 52120700100000 | AU59: =IF(LEFT(T59,2)="VO",T59,"") -> VO00462649
B60: 37284 | C60: 2002-01 | D60: 52120-7001-000-00 | E60: Parts and Materials Overhead Unal | F60: 35.59 | G60: JRNLWA00031047 | H60: From Voucher Posting. | I60: enim Auto idque | J60: Cbalderas | K60: Posted | L60: JE IC | M60: 52120 | N60: 458 | O60: Repairs and Maint | P60: 7001 | Q60: 000 | R60: 00 | S60: FALSE | T60: VO00462655 | U60: JRNL00079238 | V60: VEND1217 | W60: 514748 | X60: 37271 | Y60: 37328 | AD60: 7001 | AE60: 35.59 | AF60: ERP_Demo | AG60: ERP_Demo | AI60: USD | AJ60: 35.59 | AK60: 7 | AL60: FALSE | AM60: FALSE | AN60: FALSE | AO60: 0 | AP60: 1 | AQ60: 37284 | AR60: 37286 | AS60: 1 | AT60: 52120700100000 | AU60: =IF(LEFT(T60,2)="VO",T60,"") -> VO00462655
B61: 37284 | C61: 2002-01 | D61: 52120-7001-000-00 | E61: Parts and Materials Overhead Unal | F61: 3.85 | G61: JRNLWA00031047 | H61: From Voucher Posting. | I61: ita: Auto fusce | J61: Cbalderas | K61: Posted | L61: JE IC | M61: 52120 | N61: 458 | O61: Repairs and Maint | P61: 7001 | Q61: 000 | R61: 00 | S61: FALSE | T61: VO00462658 | U61: JRNL00079238 | V61: VEND1217 | W61: 762773 | X61: 37271 | Y61: 37328 | AD61: 7001 | AE61: 3.85 | AF61: ERP_Demo | AG61: ERP_Demo | AI61: USD | AJ61: 3.85 | AK61: 8 | AL61: FALSE | AM61: FALSE | AN61: FALSE | AO61: 0 | AP61: 1 | AQ61: 37284 | AR61: 37286 | AS61: 1 | AT61: 52120700100000 | AU61: =IF(LEFT(T61,2)="VO",T61,"") -> VO00462658
... B76: 37286 | C76: 2002-01 | D76: 52200-7001-000-00 | E76: Office Supply and Equip Overhead | F76: 26.72 | G76: JRNLWA00031116 | H76: From Voucher Posting. | I76: nostrum dapibus | J76: Cbalderas | K76: Posted | L76: JE IC | M76: 52200 | N76: 459 | O76: Facility Expense | P76: 7001 | Q76: 000 | R76: 00 | S76: FALSE | T76: VO00464685 | U76: JRNL00079391 | V76: VEND0776 | W76: 4-276-81615 | X76: 37281 | Y76: 37291 | AD76: 7015 | AE76: 89.22 | AF76: ERP_Demo | AG76: ERP_Demo | AI76: USD | AJ76: 26.72 | AK76: 18 | AL76: FALSE | AM76: FALSE | AN76: FALSE | AO76: 0 | AP76: 1 | AQ76: 37286 | AR76: 37288 | AS76: 1 | AT76: 52200700100000 | AU76: =IF(LEFT(T76,2)="VO",T76,"") -> VO00464685
B77: 37287 | C77: 2002-01 | D77: 31000-7002-000-00 | E77: Hauling Revenue - Roll Off Permanent Che | F77: -5966.9 | G77: JRNLWA00031644 | H77: January | I77: January | K77: Posted | L77: JE STD | M77: 31000 | N77: 400 | O77: Revenue - Sales | P77: 7002 | Q77: 000 | R77: 00 | S77: FALSE | T77: JRNLWA00031644 | X77: 2 | Y77: 2 | AE77: 0 | AF77: ERP_Demo | AG77: ERP_Demo | AI77: USD | AJ77: -5966.9 | AK77: 3 | AL77: FALSE | AM77: FALSE | AN77: FALSE | AO77: 0 | AP77: 1 | AQ77: 37287 | AR77: 37294 | AS77: 1 | AT77: 31000700200000 | AU77: =IF(LEFT(T77,2)="VO",T77,"")
...

Sheet PL Example
B1: PL Trend Report
B2: 3 Month Trend | G2: Location: | H2: 7001
G3: Month: | H3: 2002-04
G6: TREND DATA
G7: =IFERROR(EOMONTH(DATEVALUE(H3&"-01"),-2),"-") -> 37315 | H7: =IFERROR(EOMONTH(G7,1),"-") -> 37346 | I7: =IFERROR(EOMONTH(H7,1),"-") -> 37376
C9: Revenue - Sales | G9: 113648.97 | H9: 112253.16 | I9: 116661.33
C10: Revenue - Other | G10: 6 | H10: 6 | I10: 6
C12: Revenue | G12: =SUM(G9:G11) -> 113654.97 | H12: =+H10+H9 -> 112259.16 | I12: =+I10+I9 -> 116667.33
C14: Revenue Reductions | G14: 37136.05 | H14: 35548.8 | I14: 40933.95
C16: Net Revenue | G16: =+G12-G14 -> 76518.92 | H16: =+H12-H14 -> 76710.36 | I16: =+I12-I14 -> 75733.38
C18: Salary and Wages | G18: 34488.77 | H18: 37233.27 | I18: 39175.58
C19: Benefits | G19: 6078.93 | H19: 7214 | I19: 6083.78
C20: Repairs and Maint | G20: 6161.57 | H20: 9160.45 | I20: 10141.94
C21: Facility Expense | G21: 2114 | H21: 2413.09 | I21: 2167.95
C22: Insurance | G22: 4870.28 | H22: 4899.82 | I22: 5711.26
C23: Bad Deb Expense | G23: 0 | H23: 0 | I23: 0
C24: Other Operating Expenses | G24: 0 | H24: 0 | I24: 0
C25: G&A | G25: 5414.97 | H25: 6771.19 | I25: 6699.19
C27: Cost of Ops | G27: =SUM(G18:G25) -> 59128.52 | H27: =SUM(H18:H25) -> 67691.82 | I27: =SUM(I18:I25) -> 69979.7
C30: EBITDA | G30: =+G16-G27 -> 17390.4 | H30: =+H16-H27 -> 9018.54 | I30: =+I16-I27 -> 5753.68
B32: Watch list EBITDA | G32: =G30 +G23+SUMIF(#REF!,52141,G:G)+SUMIF(#REF!,52142,G:G)+SUMIF(#REF!,52143,G:G)+SUMIF(#REF!,55142,G:G)+SUMIF(#REF!,56142,G:G)+SUMIF(#REF!,70142,G:G) -> #REF! | H32: =H30 +H23+SUMIF(#REF!,52141,H:H)+SUMIF(#REF!,52142,H:H)+SUMIF(#REF!,52143,H:H)+SUMIF(#REF!,55142,H:H)+SUMIF(#REF!,56142,H:H)+SUMIF(#REF!,70142,H:H) -> #REF! | I32: =I30 +I23+SUMIF(#REF!,52141,I:I)+SUMIF(#REF!,52142,I:I)+SUMIF(#REF!,52143,I:I)+SUMIF(#REF!,55142,I:I)+SUMIF(#REF!,56142,I:I)+SUMIF(#REF!,70142,I:I) -> #REF!
C34: Depreciation Expense | G34: 5278.93 | H34: 5278.94 | I34: 5278.92
C35: Amortization Expense | G35: 416.66 | H35: 416.67 | I35: 416.67
C36: Depletion Expense | G36: 0 | H36: 0 | I36: 0
C38: Total DDA | G38: =SUM(G34:G37) -> 5695.59 | H38: =+H36+H34+H35 -> 5695.61 | I38: =+I36+I34+I35 -> 5695.59
C40: EBIT From Ops | G40: =+G30-G38 -> 11694.81 | H40: =+H30-H38 -> 3322.93 | I40: =+I30-I38 -> 58.09
C42: Interest Expense | G42: -260.54 | H42: 62.71 | I42: -272.37
C43: Gain/Loss on Sale of Asset | G43: 0 | H43: 0 | I43: 0
C45: NI b/ Taxes | G45: =SUM(G42:G44)+G40 -> 11434.27 | H45: =+H40-H42-H43 -> 3260.22 | I45: =SUM(I42:I44) -> -272.37
C47: Taxes | G47: 0 | H47: 0 | I47: 0
C49: Net Income | G49: =++G45-G47 -> 11434.27 | H49: =++H45-H47 -> 3260.22 | I49: =++I45-I47 -> -272.37
